Workbook

Sheet Ensaios
A1: Arquivo | B1: Pasta | C1: Potência (W) | D1: Rotação (RPM) | E1: f elétrica (Hz) | F1: Código resistores | G1: Braços ativos | H1: Capacitância (µF) | I1: R braços resistor (Ω) | J1: Resistência série (Ω) | K1: Data/hora do ensaio | L1: Status | M1: Usar na análise | N1: Observação
A2: 7Bracos_2700_R0001_80W_2026-10-09_12_20.csv | B2: 80W_2700RPM_R0001 | C2: 80 | D2: 2700 | E2: =D2*2/60 | F2: 0001 | G2: 7 | H2: =INDEX(Parametros!$B$2:$B$9,MATCH(G2,Parametros!$A$2:$A$9,0)) | I2: =1/(VALUE(MID(F2,1,1))/Parametros!$E$2+VALUE(MID(F2,2,1))/Parametros!$E$3+VALUE(MID(F2,3,1))/Parametros!$E$4+VALUE(MID(F2,4,1))/Parametros!$E$5) | J2: =IF(G2=0,Parametros!$E$8,Parametros!$E$6+Parametros!$E$6*(Parametros!$E$7/G2+I2)/(Parametros!$E$6+Parametros!$E$7/G2+I2)) | K2: 2026-10-09 12:20 | L2: Válido | M2: =IF(L2="Válido","Sim","Não")
A3: 6Bracos_2700_R0001_80W_2026-10-09_12_20.csv | B3: 80W_2700RPM_R0001 | C3: 80 | D3: 2700 | E3: =D3*2/60 | F3: 0001 | G3: 6 | H3: =INDEX(Parametros!$B$2:$B$9,MATCH(G3,Parametros!$A$2:$A$9,0)) | I3: =1/(VALUE(MID(F3,1,1))/Parametros!$E$2+VALUE(MID(F3,2,1))/Parametros!$E$3+VALUE(MID(F3,3,1))/Parametros!$E$4+VALUE(MID(F3,4,1))/Parametros!$E$5) | J3: =IF(G3=0,Parametros!$E$8,Parametros!$E$6+Parametros!$E$6*(Parametros!$E$7/G3+I3)/(Parametros!$E$6+Parametros!$E$7/G3+I3)) | K3: 2026-10-09 12:20 | L3: Válido | M3: =IF(L3="Válido","Sim","Não")
A4: 5Bracos_2700_R0001_80W_2026-10-09_12_20.csv | B4: 80W_2700RPM_R0001 | C4: 80 | D4: 2700 | E4: =D4*2/60 | F4: 0001 | G4: 5 | H4: =INDEX(Parametros!$B$2:$B$9,MATCH(G4,Parametros!$A$2:$A$9,0)) | I4: =1/(VALUE(MID(F4,1,1))/Parametros!$E$2+VALUE(MID(F4,2,1))/Parametros!$E$3+VALUE(MID(F4,3,1))/Parametros!$E$4+VALUE(MID(F4,4,1))/Parametros!$E$5) | J4: =IF(G4=0,Parametros!$E$8,Parametros!$E$6+Parametros!$E$6*(Parametros!$E$7/G4+I4)/(Parametros!$E$6+Parametros!$E$7/G4+I4)) | K4: 2026-10-09 12:20 | L4: Válido | M4: =IF(L4="Válido","Sim","Não")
A5: 4Bracos_2700_R0001_80W_2026-10-09_12_20.csv | B5: 80W_2700RPM_R0001 | C5: 80 | D5: 2700 | E5: =D5*2/60 | F5: 0001 | G5: 4 | H5: =INDEX(Parametros!$B$2:$B$9,MATCH(G5,Parametros!$A$2:$A$9,0)) | I5: =1/(VALUE(MID(F5,1,1))/Parametros!$E$2+VALUE(MID(F5,2,1))/Parametros!$E$3+VALUE(MID(F5,3,1))/Parametros!$E$4+VALUE(MID(F5,4,1))/Parametros!$E$5) | J5: =IF(G5=0,Parametros!$E$8,Parametros!$E$6+Parametros!$E$6*(Parametros!$E$7/G5+I5)/(Parametros!$E$6+Parametros!$E$7/G5+I5)) | K5: 2026-10-09 12:20 | L5: Válido | M5: =IF(L5="Válido","Sim","Não")
A6: 3Bracos_2700_R0001_80W_2026-10-09_12_20.csv | B6: 80W_2700RPM_R0001 | C6: 80 | D6: 2700 | E6: =D6*2/60 | F6: 0001 | G6: 3 | H6: =INDEX(Parametros!$B$2:$B$9,MATCH(G6,Parametros!$A$2:$A$9,0)) | I6: =1/(VALUE(MID(F6,1,1))/Parametros!$E$2+VALUE(MID(F6,2,1))/Parametros!$E$3+VALUE(MID(F6,3,1))/Parametros!$E$4+VALUE(MID(F6,4,1))/Parametros!$E$5) | J6: =IF(G6=0,Parametros!$E$8,Parametros!$E$6+Parametros!$E$6*(Parametros!$E$7/G6+I6)/(Parametros!$E$6+Parametros!$E$7/G6+I6)) | K6: 2026-10-09 12:20 | L6: Válido | M6: =IF(L6="Válido","Sim","Não")
A7: 2Bracos_2700_R0001_80W_2026-10-09_12_20.csv | B7: 80W_2700RPM_R0001 | C7: 80 | D7: 2700 | E7: =D7*2/60 | F7: 0001 | G7: 2 | H7: =INDEX(Parametros!$B$2:$B$9,MATCH(G7,Parametros!$A$2:$A$9,0)) | I7: =1/(VALUE(MID(F7,1,1))/Parametros!$E$2+VALUE(MID(F7,2,1))/Parametros!$E$3+VALUE(MID(F7,3,1))/Parametros!$E$4+VALUE(MID(F7,4,1))/Parametros!$E$5) | J7: =IF(G7=0,Parametros!$E$8,Parametros!$E$6+Parametros!$E$6*(Parametros!$E$7/G7+I7)/(Parametros!$E$6+Parametros!$E$7/G7+I7)) | K7: 2026-10-09 12:20 | L7: Válido | M7: =IF(L7="Válido","Sim","Não")
A8: 1Bracos_2700_R0001_80W_2026-10-09_12_20.csv | B8: 80W_2700RPM_R0001 | C8: 80 | D8: 2700 | E8: =D8*2/60 | F8: 0001 | G8: 1 | H8: =INDEX(Parametros!$B$2:$B$9,MATCH(G8,Parametros!$A$2:$A$9,0)) | I8: =1/(VALUE(MID(F8,1,1))/Parametros!$E$2+VALUE(MID(F8,2,1))/Parametros!$E$3+VALUE(MID(F8,3,1))/Parametros!$E$4+VALUE(MID(F8,4,1))/Parametros!$E$5) | J8: =IF(G8=0,Parametros!$E$8,Parametros!$E$6+Parametros!$E$6*(Parametros!$E$7/G8+I8)/(Parametros!$E$6+Parametros!$E$7/G8+I8)) | K8: 2026-10-09 12:20 | L8: Válido | M8: =IF(L8="Válido","Sim","Não")
A9: 0Bracos_2700_R0001_80W_2026-10-09_12_20.csv | B9: 80W_2700RPM_R0001 | C9: 80 | D9: 2700 | E9: =D9*2/60 | F9: 0001 | G9: 0 | H9: =INDEX(Parametros!$B$2:$B$9,MATCH(G9,Parametros!$A$2:$A$9,0)) | I9: =1/(VALUE(MID(F9,1,1))/Parametros!$E$2+VALUE(MID(F9,2,1))/Parametros!$E$3+VALUE(MID(F9,3,1))/Parametros!$E$4+VALUE(MID(F9,4,1))/Parametros!$E$5) | J9: =IF(G9=0,Parametros!$E$8,Parametros!$E$6+Parametros!$E$6*(Parametros!$E$7/G9+I9)/(Parametros!$E$6+Parametros!$E$7/G9+I9)) | K9: 2026-10-09 12:20 | L9: Válido | M9: =IF(L9="Válido","Sim","Não")
A10: 7Bracos_2700_R0010_80W_2026-10-09_12_20.csv | B10: 80W_2700RPM_R0010 | C10: 80 | D10: 2700 | E10: =D10*2/60 | F10: 0010 | G10: 7 | H10: =INDEX(Parametros!$B$2:$B$9,MATCH(G10,Parametros!$A$2:$A$9,0)) | I10: =1/(VALUE(MID(F10,1,1))/Parametros!$E$2+VALUE(MID(F10,2,1))/Parametros!$E$3+VALUE(MID(F10,3,1))/Parametros!$E$4+VALUE(MID(F10,4,1))/Parametros!$E$5) | J10: =IF(G10=0,Parametros!$E$8,Parametros!$E$6+Parametros!$E$6*(Parametros!$E$7/G10+I10)/(Parametros!$E$6+Parametros!$E$7/G10+I10)) | K10: 2026-10-09 12:20 | L10: Válido | M10: =IF(L10="Válido","Sim","Não")
A11: 6Bracos_2700_R0010_80W_2026-10-09_12_20.csv | B11: 80W_2700RPM_R0010 | C11: 80 | D11: 2700 | E11: =D11*2/60 | F11: 0010 | G11: 6 | H11: =INDEX(Parametros!$B$2:$B$9,MATCH(G11,Parametros!$A$2:$A$9,0)) | I11: =1/(VALUE(MID(F11,1,1))/Parametros!$E$2+VALUE(MID(F11,2,1))/Parametros!$E$3+VALUE(MID(F11,3,1))/Parametros!$E$4+VALUE(MID(F11,4,1))/Parametros!$E$5) | J11: =IF(G11=0,Parametros!$E$8,Parametros!$E$6+Parametros!$E$6*(Parametros!$E$7/G11+I11)/(Parametros!$E$6+Parametros!$E$7/G11+I11)) | K11: 2026-10-09 12:20 | L11: Válido | M11: =IF(L11="Válido","Sim","Não")
A12: 5Bracos_2700_R0010_80W_2026-10-09_12_20.csv | B12: 80W_2700RPM_R0010 | C12: 80 | D12: 2700 | E12: =D12*2/60 | F12: 0010 | G12: 5 | H12: =INDEX(Parametros!$B$2:$B$9,MATCH(G12,Parametros!$A$2:$A$9,0)) | I12: =1/(VALUE(MID(F12,1,1))/Parametros!$E$2+VALUE(MID(F12,2,1))/Parametros!$E$3+VALUE(MID(F12,3,1))/Parametros!$E$4+VALUE(MID(F12,4,1))/Parametros!$E$5) | J12: =IF(G12=0,Parametros!$E$8,Parametros!$E$6+Parametros!$E$6*(Parametros!$E$7/G12+I12)/(Parametros!$E$6+Parametros!$E$7/G12+I12)) | K12: 2026-10-09 12:20 | L12: Válido | M12: =IF(L12="Válido","Sim","Não")
A13: 4Bracos_2700_R0010_80W_2026-10-09_12_20.csv | B13: 80W_2700RPM_R0010 | C13: 80 | D13: 2700 | E13: =D13*2/60 | F13: 0010 | G13: 4 | H13: =INDEX(Parametros!$B$2:$B$9,MATCH(G13,Parametros!$A$2:$A$9,0)) | I13: =1/(VALUE(MID(F13,1,1))/Parametros!$E$2+VALUE(MID(F13,2,1))/Parametros!$E$3+VALUE(MID(F13,3,1))/Parametros!$E$4+VALUE(MID(F13,4,1))/Parametros!$E$5) | J13: =IF(G13=0,Parametros!$E$8,Parametros!$E$6+Parametros!$E$6*(Parametros!$E$7/G13+I13)/(Parametros!$E$6+Parametros!$E$7/G13+I13)) | K13: 2026-10-09 12:20 | L13: Válido | M13: =IF(L13="Válido","Sim","Não")
... A57: 0Bracos_2700_R0111_80W_2026-10-09_12_20.csv | B57: 80W_2700RPM_R0111 | C57: 80 | D57: 2700 | E57: =D57*2/60 | F57: 0111 | G57: 0 | H57: =INDEX(Parametros!$B$2:$B$9,MATCH(G57,Parametros!$A$2:$A$9,0)) | I57: =1/(VALUE(MID(F57,1,1))/Parametros!$E$2+VALUE(MID(F57,2,1))/Parametros!$E$3+VALUE(MID(F57,3,1))/Parametros!$E$4+VALUE(MID(F57,4,1))/Parametros!$E$5) | J57: =IF(G57=0,Parametros!$E$8,Parametros!$E$6+Parametros!$E$6*(Parametros!$E$7/G57+I57)/(Parametros!$E$6+Parametros!$E$7/G57+I57)) | K57: 2026-10-09 12:20 | L57: Válido | M57: =IF(L57="Válido","Sim","Não")
A58: 7Bracos_2700_R1000_80W_2026-10-09_12_20.csv | B58: 80W_2700RPM_R1000 | C58: 80 | D58: 2700 | E58: =D58*2/60 | F58: 1000 | G58: 7 | H58: =INDEX(Parametros!$B$2:$B$9,MATCH(G58,Parametros!$A$2:$A$9,0)) | I58: =1/(VALUE(MID(F58,1,1))/Parametros!$E$2+VALUE(MID(F58,2,1))/Parametros!$E$3+VALUE(MID(F58,3,1))/Parametros!$E$4+VALUE(MID(F58,4,1))/Parametros!$E$5) | J58: =IF(G58=0,Parametros!$E$8,Parametros!$E$6+Parametros!$E$6*(Parametros!$E$7/G58+I58)/(Parametros!$E$6+Parametros!$E$7/G58+I58)) | K58: 2026-10-09 12:20 | L58: Patamar baixo de ripple (suspeita DAQ) | M58: =IF(L58="Válido","Sim","Não") | N58: Ripple x C mediano da config = 577 (esperado ~730 a 80W)
A59: 6Bracos_2700_R1000_80W_2026-10-09_12_20.csv | B59: 80W_2700RPM_R1000 | C59: 80 | D59: 2700 | E59: =D59*2/60 | F59: 1000 | G59: 6 | H59: =INDEX(Parametros!$B$2:$B$9,MATCH(G59,Parametros!$A$2:$A$9,0)) | I59: =1/(VALUE(MID(F59,1,1))/Parametros!$E$2+VALUE(MID(F59,2,1))/Parametros!$E$3+VALUE(MID(F59,3,1))/Parametros!$E$4+VALUE(MID(F59,4,1))/Parametros!$E$5) | J59: =IF(G59=0,Parametros!$E$8,Parametros!$E$6+Parametros!$E$6*(Parametros!$E$7/G59+I59)/(Parametros!$E$6+Parametros!$E$7/G59+I59)) | K59: 2026-10-09 12:20 | L59: Patamar baixo de ripple (suspeita DAQ) | M59: =IF(L59="Válido","Sim","Não") | N59: Ripple x C mediano da config = 577 (esperado ~730 a 80W)
A60: 5Bracos_2700_R1000_80W_2026-10-09_12_20.csv | B60: 80W_2700RPM_R1000 | C60: 80 | D60: 2700 | E60: =D60*2/60 | F60: 1000 | G60: 5 | H60: =INDEX(Parametros!$B$2:$B$9,MATCH(G60,Parametros!$A$2:$A$9,0)) | I60: =1/(VALUE(MID(F60,1,1))/Parametros!$E$2+VALUE(MID(F60,2,1))/Parametros!$E$3+VALUE(MID(F60,3,1))/Parametros!$E$4+VALUE(MID(F60,4,1))/Parametros!$E$5) | J60: =IF(G60=0,Parametros!$E$8,Parametros!$E$6+Parametros!$E$6*(Parametros!$E$7/G60+I60)/(Parametros!$E$6+Parametros!$E$7/G60+I60)) | K60: 2026-10-09 12:20 | L60: Patamar baixo de ripple (suspeita DAQ) | M60: =IF(L60="Válido","Sim","Não") | N60: Ripple x C mediano da config = 577 (esperado ~730 a 80W)
A61: 4Bracos_2700_R1000_80W_2026-10-09_12_20.csv | B61: 80W_2700RPM_R1000 | C61: 80 | D61: 2700 | E61: =D61*2/60 | F61: 1000 | G61: 4 | H61: =INDEX(Parametros!$B$2:$B$9,MATCH(G61,Parametros!$A$2:$A$9,0)) | I61: =1/(VALUE(MID(F61,1,1))/Parametros!$E$2+VALUE(MID(F61,2,1))/Parametros!$E$3+VALUE(MID(F61,3,1))/Parametros!$E$4+VALUE(MID(F61,4,1))/Parametros!$E$5) | J61: =IF(G61=0,Parametros!$E$8,Parametros!$E$6+Parametros!$E$6*(Parametros!$E$7/G61+I61)/(Parametros!$E$6+Parametros!$E$7/G61+I61)) | K61: 2026-10-09 12:20 | L61: Patamar baixo de ripple (suspeita DAQ) | M61: =IF(L61="Válido","Sim","Não") | N61: Ripple x C mediano da config = 577 (esperado ~730 a 80W)
A62: 3Bracos_2700_R1000_80W_2026-10-09_12_20.csv | B62: 80W_2700RPM_R1000 | C62: 80 | D62: 2700 | E62: =D62*2/60 | F62: 1000 | G62: 3 | H62: =INDEX(Parametros!$B$2:$B$9,MATCH(G62,Parametros!$A$2:$A$9,0)) | I62: =1/(VALUE(MID(F62,1,1))/Parametros!$E$2+VALUE(MID(F62,2,1))/Parametros!$E$3+VALUE(MID(F62,3,1))/Parametros!$E$4+VALUE(MID(F62,4,1))/Parametros!$E$5) | J62: =IF(G62=0,Parametros!$E$8,Parametros!$E$6+Parametros!$E$6*(Parametros!$E$7/G62+I62)/(Parametros!$E$6+Parametros!$E$7/G62+I62)) | K62: 2026-10-09 12:20 | L62: Patamar baixo de ripple (suspeita DAQ) | M62: =IF(L62="Válido","Sim","Não") | N62: Ripple x C mediano da config = 577 (esperado ~730 a 80W)
A63: 2Bracos_2700_R1000_80W_2026-10-09_12_20.csv | B63: 80W_2700RPM_R1000 | C63: 80 | D63: 2700 | E63: =D63*2/60 | F63: 1000 | G63: 2 | H63: =INDEX(Parametros!$B$2:$B$9,MATCH(G63,Parametros!$A$2:$A$9,0)) | I63: =1/(VALUE(MID(F63,1,1))/Parametros!$E$2+VALUE(MID(F63,2,1))/Parametros!$E$3+VALUE(MID(F63,3,1))/Parametros!$E$4+VALUE(MID(F63,4,1))/Parametros!$E$5) | J63: =IF(G63=0,Parametros!$E$8,Parametros!$E$6+Parametros!$E$6*(Parametros!$E$7/G63+I63)/(Parametros!$E$6+Parametros!$E$7/G63+I63)) | K63: 2026-10-09 12:20 | L63: Patamar baixo de ripple (suspeita DAQ) | M63: =IF(L63="Válido","Sim","Não") | N63: Ripple x C mediano da config = 577 (esperado ~730 a 80W)
A64: 1Bracos_2700_R1000_80W_2026-10-09_12_20.csv | B64: 80W_2700RPM_R1000 | C64: 80 | D64: 2700 | E64: =D64*2/60 | F64: 1000 | G64: 1 | H64: =INDEX(Parametros!$B$2:$B$9,MATCH(G64,Parametros!$A$2:$A$9,0)) | I64: =1/(VALUE(MID(F64,1,1))/Parametros!$E$2+VALUE(MID(F64,2,1))/Parametros!$E$3+VALUE(MID(F64,3,1))/Parametros!$E$4+VALUE(MID(F64,4,1))/Parametros!$E$5) | J64: =IF(G64=0,Parametros!$E$8,Parametros!$E$6+Parametros!$E$6*(Parametros!$E$7/G64+I64)/(Parametros!$E$6+Parametros!$E$7/G64+I64)) | K64: 2026-10-09 12:20 | L64: Patamar baixo de ripple (suspeita DAQ) | M64: =IF(L64="Válido","Sim","Não") | N64: Ripple x C mediano da config = 577 (esperado ~730 a 80W)
A65: 0Bracos_2700_R1000_80W_2026-10-09_12_20.csv | B65: 80W_2700RPM_R1000 | C65: 80 | D65: 2700 | E65: =D65*2/60 | F65: 1000 | G65: 0 | H65: =INDEX(Parametros!$B$2:$B$9,MATCH(G65,Parametros!$A$2:$A$9,0)) | I65: =1/(VALUE(MID(F65,1,1))/Parametros!$E$2+VALUE(MID(F65,2,1))/Parametros!$E$3+VALUE(MID(F65,3,1))/Parametros!$E$4+VALUE(MID(F65,4,1))/Parametros!$E$5) | J65: =IF(G65=0,Parametros!$E$8,Parametros!$E$6+Parametros!$E$6*(Parametros!$E$7/G65+I65)/(Parametros!$E$6+Parametros!$E$7/G65+I65)) | K65: 2026-10-09 12:20 | L65: Patamar baixo de ripple (suspeita DAQ) | M65: =IF(L65="Válido","Sim","Não") | N65: Ripple x C mediano da config = 577 (esperado ~730 a 80W)
A66: 7Bracos_2700_R1001_80W_2026-10-09_12_20.csv | B66: 80W_2700RPM_R1001 | C66: 80 | D66: 2700 | E66: =D66*2/60 | F66: 1001 | G66: 7 | H66: =INDEX(Parametros!$B$2:$B$9,MATCH(G66,Parametros!$A$2:$A$9,0)) | I66: =1/(VALUE(MID(F66,1,1))/Parametros!$E$2+VALUE(MID(F66,2,1))/Parametros!$E$3+VALUE(MID(F66,3,1))/Parametros!$E$4+VALUE(MID(F66,4,1))/Parametros!$E$5) | J66: =IF(G66=0,Parametros!$E$8,Parametros!$E$6+Parametros!$E$6*(Parametros!$E$7/G66+I66)/(Parametros!$E$6+Parametros!$E$7/G66+I66)) | K66: 2026-10-09 12:20 | L66: Patamar baixo de ripple (suspeita DAQ) | M66: =IF(L66="Válido","Sim","Não") | N66: Ripple x C mediano da config = 514 (esperado ~730 a 80W)
A67: 6Bracos_2700_R1001_80W_2026-10-09_12_20.csv | B67: 80W_2700RPM_R1001 | C67: 80 | D67: 2700 | E67: =D67*2/60 | F67: 1001 | G67: 6 | H67: =INDEX(Parametros!$B$2:$B$9,MATCH(G67,Parametros!$A$2:$A$9,0)) | I67: =1/(VALUE(MID(F67,1,1))/Parametros!$E$2+VALUE(MID(F67,2,1))/Parametros!$E$3+VALUE(MID(F67,3,1))/Parametros!$E$4+VALUE(MID(F67,4,1))/Parametros!$E$5) | J67: =IF(G67=0,Parametros!$E$8,Parametros!$E$6+Parametros!$E$6*(Parametros!$E$7/G67+I67)/(Parametros!$E$6+Parametros!$E$7/G67+I67)) | K67: 2026-10-09 12:20 | L67: Patamar baixo de ripple (suspeita DAQ) | M67: =IF(L67="Válido","Sim","Não") | N67: Ripple x C mediano da config = 514 (esperado ~730 a 80W)
A68: 5Bracos_2700_R1001_80W_2026-10-09_12_20.csv | B68: 80W_2700RPM_R1001 | C68: 80 | D68: 2700 | E68: =D68*2/60 | F68: 1001 | G68: 5 | H68: =INDEX(Parametros!$B$2:$B$9,MATCH(G68,Parametros!$A$2:$A$9,0)) | I68: =1/(VALUE(MID(F68,1,1))/Parametros!$E$2+VALUE(MID(F68,2,1))/Parametros!$E$3+VALUE(MID(F68,3,1))/Parametros!$E$4+VALUE(MID(F68,4,1))/Parametros!$E$5) | J68: =IF(G68=0,Parametros!$E$8,Parametros!$E$6+Parametros!$E$6*(Parametros!$E$7/G68+I68)/(Parametros!$E$6+Parametros!$E$7/G68+I68)) | K68: 2026-10-09 12:20 | L68: Patamar baixo de ripple (suspeita DAQ) | M68: =IF(L68="Válido","Sim","Não") | N68: Ripple x C mediano da config = 514 (esperado ~730 a 80W)
A69: 4Bracos_2700_R1001_80W_2026-10-09_12_20.csv | B69: 80W_2700RPM_R1001 | C69: 80 | D69: 2700 | E69: =D69*2/60 | F69: 1001 | G69: 4 | H69: =INDEX(Parametros!$B$2:$B$9,MATCH(G69,Parametros!$A$2:$A$9,0)) | I69: =1/(VALUE(MID(F69,1,1))/Parametros!$E$2+VALUE(MID(F69,2,1))/Parametros!$E$3+VALUE(MID(F69,3,1))/Parametros!$E$4+VALUE(MID(F69,4,1))/Parametros!$E$5) | J69: =IF(G69=0,Parametros!$E$8,Parametros!$E$6+Parametros!$E$6*(Parametros!$E$7/G69+I69)/(Parametros!$E$6+Parametros!$E$7/G69+I69)) | K69: 2026-10-09 12:20 | L69: Patamar baixo de ripple (suspeita DAQ) | M69: =IF(L69="Válido","Sim","Não") | N69: Ripple x C mediano da config = 514 (esperado ~730 a 80W)
... A97: 0Bracos_2700_R1100_80W_2026-10-09_12_20.csv | B97: 80W_2700RPM_R1100 | C97: 80 | D97: 2700 | E97: =D97*2/60 | F97: 1100 | G97: 0 | H97: =INDEX(Parametros!$B$2:$B$9,MATCH(G97,Parametros!$A$2:$A$9,0)) | I97: =1/(VALUE(MID(F97,1,1))/Parametros!$E$2+VALUE(MID(F97,2,1))/Parametros!$E$3+VALUE(MID(F97,3,1))/Parametros!$E$4+VALUE(MID(F97,4,1))/Parametros!$E$5) | J97: =IF(G97=0,Parametros!$E$8,Parametros!$E$6+Parametros!$E$6*(Parametros!$E$7/G97+I97)/(Parametros!$E$6+Parametros!$E$7/G97+I97)) | K97: 2026-10-09 12:20 | L97: Patamar baixo de ripple (suspeita DAQ) | M97: =IF(L97="Válido","Sim","Não") | N97: Ripple x C mediano da config = 589 (esperado ~730 a 80W)
A98: 7Bracos_2700_R1101_80W_2026-10-09_12_20.csv | B98: 80W_2700RPM_R1101 | C98: 80 | D98: 2700 | E98: =D98*2/60 | F98: 1101 | G98: 7 | H98: =INDEX(Parametros!$B$2:$B$9,MATCH(G98,Parametros!$A$2:$A$9,0)) | I98: =1/(VALUE(MID(F98,1,1))/Parametros!$E$2+VALUE(MID(F98,2,1))/Parametros!$E$3+VALUE(MID(F98,3,1))/Parametros!$E$4+VALUE(MID(F98,4,1))/Parametros!$E$5) | J98: =IF(G98=0,Parametros!$E$8,Parametros!$E$6+Parametros!$E$6*(Parametros!$E$7/G98+I98)/(Parametros!$E$6+Parametros!$E$7/G98+I98)) | K98: 2026-10-09 12:20 | L98: Válido | M98: =IF(L98="Válido","Sim","Não")
A99: 6Bracos_2700_R1101_80W_2026-10-09_12_20.csv | B99: 80W_2700RPM_R1101 | C99: 80 | D99: 2700 | E99: =D99*2/60 | F99: 1101 | G99: 6 | H99: =INDEX(Parametros!$B$2:$B$9,MATCH(G99,Parametros!$A$2:$A$9,0)) | I99: =1/(VALUE(MID(F99,1,1))/Parametros!$E$2+VALUE(MID(F99,2,1))/Parametros!$E$3+VALUE(MID(F99,3,1))/Parametros!$E$4+VALUE(MID(F99,4,1))/Parametros!$E$5) | J99: =IF(G99=0,Parametros!$E$8,Parametros!$E$6+Parametros!$E$6*(Parametros!$E$7/G99+I99)/(Parametros!$E$6+Parametros!$E$7/G99+I99)) | K99: 2026-10-09 12:20 | L99: Válido | M99: =IF(L99="Válido","Sim","Não")
A100: 5Bracos_2700_R1101_80W_2026-10-09_12_20.csv | B100: 80W_2700RPM_R1101 | C100: 80 | D100: 2700 | E100: =D100*2/60 | F100: 1101 | G100: 5 | H100: =INDEX(Parametros!$B$2:$B$9,MATCH(G100,Parametros!$A$2:$A$9,0)) | I100: =1/(VALUE(MID(F100,1,1))/Parametros!$E$2+VALUE(MID(F100,2,1))/Parametros!$E$3+VALUE(MID(F100,3,1))/Parametros!$E$4+VALUE(MID(F100,4,1))/Parametros!$E$5) | J100: =IF(G100=0,Parametros!$E$8,Parametros!$E$6+Parametros!$E$6*(Parametros!$E$7/G100+I100)/(Parametros!$E$6+Parametros!$E$7/G100+I100)) | K100: 2026-10-09 12:20 | L100: Válido | M100: =IF(L100="Válido","Sim","Não")
A101: 4Bracos_2700_R1101_80W_2026-10-09_12_20.csv | B101: 80W_2700RPM_R1101 | C101: 80 | D101: 2700 | E101: =D101*2/60 | F101: 1101 | G101: 4 | H101: =INDEX(Parametros!$B$2:$B$9,MATCH(G101,Parametros!$A$2:$A$9,0)) | I101: =1/(VALUE(MID(F101,1,1))/Parametros!$E$2+VALUE(MID(F101,2,1))/Parametros!$E$3+VALUE(MID(F101,3,1))/Parametros!$E$4+VALUE(MID(F101,4,1))/Parametros!$E$5) | J101: =IF(G101=0,Parametros!$E$8,Parametros!$E$6+Parametros!$E$6*(Parametros!$E$7/G101+I101)/(Parametros!$E$6+Parametros!$E$7/G101+I101)) | K101: 2026-10-09 12:20 | L101: Válido | M101: =IF(L101="Válido","Sim","Não")
A102: 3Bracos_2700_R1101_80W_2026-10-09_12_20.csv | B102: 80W_2700RPM_R1101 | C102: 80 | D102: 2700 | E102: =D102*2/60 | F102: 1101 | G102: 3 | H102: =INDEX(Parametros!$B$2:$B$9,MATCH(G102,Parametros!$A$2:$A$9,0)) | I102: =1/(VALUE(MID(F102,1,1))/Parametros!$E$2+VALUE(MID(F102,2,1))/Parametros!$E$3+VALUE(MID(F102,3,1))/Parametros!$E$4+VALUE(MID(F102,4,1))/Parametros!$E$5) | J102: =IF(G102=0,Parametros!$E$8,Parametros!$E$6+Parametros!$E$6*(Parametros!$E$7/G102+I102)/(Parametros!$E$6+Parametros!$E$7/G102+I102)) | K102: 2026-10-09 12:20 | L102: Válido | M102: =IF(L102="Válido","Sim","Não")
A103: 2Bracos_2700_R1101_80W_2026-10-09_12_20.csv | B103: 80W_2700RPM_R1101 | C103: 80 | D103: 2700 | E103: =D103*2/60 | F103: 1101 | G103: 2 | H103: =INDEX(Parametros!$B$2:$B$9,MATCH(G103,Parametros!$A$2:$A$9,0)) | I103: =1/(VALUE(MID(F103,1,1))/Parametros!$E$2+VALUE(MID(F103,2,1))/Parametros!$E$3+VALUE(MID(F103,3,1))/Parametros!$E$4+VALUE(MID(F103,4,1))/Parametros!$E$5) | J103: =IF(G103=0,Parametros!$E$8,Parametros!$E$6+Parametros!$E$6*(Parametros!$E$7/G103+I103)/(Parametros!$E$6+Parametros!$E$7/G103+I103)) | K103: 2026-10-09 12:20 | L103: Válido | M103: =IF(L103="Válido","Sim","Não")
A104: 1Bracos_2700_R1101_80W_2026-10-09_12_20.csv | B104: 80W_2700RPM_R1101 | C104: 80 | D104: 2700 | E104: =D104*2/60 | F104: 1101 | G104: 1 | H104: =INDEX(Parametros!$B$2:$B$9,MATCH(G104,Parametros!$A$2:$A$9,0)) | I104: =1/(VALUE(MID(F104,1,1))/Parametros!$E$2+VALUE(MID(F104,2,1))/Parametros!$E$3+VALUE(MID(F104,3,1))/Parametros!$E$4+VALUE(MID(F104,4,1))/Parametros!$E$5) | J104: =IF(G104=0,Parametros!$E$8,Parametros!$E$6+Parametros!$E$6*(Parametros!$E$7/G104+I104)/(Parametros!$E$6+Parametros!$E$7/G104+I104)) | K104: 2026-10-09 12:20 | L104: Válido | M104: =IF(L104="Válido","Sim","Não")
A105: 0Bracos_2700_R1101_80W_2026-10-09_12_20.csv | B105: 80W_2700RPM_R1101 | C105: 80 | D105: 2700 | E105: =D105*2/60 | F105: 1101 | G105: 0 | H105: =INDEX(Parametros!$B$2:$B$9,MATCH(G105,Parametros!$A$2:$A$9,0)) | I105: =1/(VALUE(MID(F105,1,1))/Parametros!$E$2+VALUE(MID(F105,2,1))/Parametros!$E$3+VALUE(MID(F105,3,1))/Parametros!$E$4+VALUE(MID(F105,4,1))/Parametros!$E$5) | J105: =IF(G105=0,Parametros!$E$8,Parametros!$E$6+Parametros!$E$6*(Parametros!$E$7/G105+I105)/(Parametros!$E$6+Parametros!$E$7/G105+I105)) | K105: 2026-10-09 12:20 | L105: Válido | M105: =IF(L105="Válido","Sim","Não")
A106: 7Bracos_2700_R1110_80W_2026-10-09_12_20.csv | B106: 80W_2700RPM_R1110 | C106: 80 | D106: 2700 | E106: =D106*2/60 | F106: 1110 | G106: 7 | H106: =INDEX(Parametros!$B$2:$B$9,MATCH(G106,Parametros!$A$2:$A$9,0)) | I106: =1/(VALUE(MID(F106,1,1))/Parametros!$E$2+VALUE(MID(F106,2,1))/Parametros!$E$3+VALUE(MID(F106,3,1))/Parametros!$E$4+VALUE(MID(F106,4,1))/Parametros!$E$5) | J106: =IF(G106=0,Parametros!$E$8,Parametros!$E$6+Parametros!$E$6*(Parametros!$E$7/G106+I106)/(Parametros!$E$6+Parametros!$E$7/G106+I106)) | K106: 2026-10-09 12:20 | L106: Válido | M106: =IF(L106="Válido","Sim","Não")
A107: 6Bracos_2700_R1110_80W_2026-10-09_12_20.csv | B107: 80W_2700RPM_R1110 | C107: 80 | D107: 2700 | E107: =D107*2/60 | F107: 1110 | G107: 6 | H107: =INDEX(Parametros!$B$2:$B$9,MATCH(G107,Parametros!$A$2:$A$9,0)) | I107: =1/(VALUE(MID(F107,1,1))/Parametros!$E$2+VALUE(MID(F107,2,1))/Parametros!$E$3+VALUE(MID(F107,3,1))/Parametros!$E$4+VALUE(MID(F107,4,1))/Parametros!$E$5) | J107: =IF(G107=0,Parametros!$E$8,Parametros!$E$6+Parametros!$E$6*(Parametros!$E$7/G107+I107)/(Parametros!$E$6+Parametros!$E$7/G107+I107)) | K107: 2026-10-09 12:20 | L107: Válido | M107: =IF(L107="Válido","Sim","Não")
A108: 5Bracos_2700_R1110_80W_2026-10-09_12_20.csv | B108: 80W_2700RPM_R1110 | C108: 80 | D108: 2700 | E108: =D108*2/60 | F108: 1110 | G108: 5 | H108: =INDEX(Parametros!$B$2:$B$9,MATCH(G108,Parametros!$A$2:$A$9,0)) | I108: =1/(VALUE(MID(F108,1,1))/Parametros!$E$2+VALUE(MID(F108,2,1))/Parametros!$E$3+VALUE(MID(F108,3,1))/Parametros!$E$4+VALUE(MID(F108,4,1))/Parametros!$E$5) | J108: =IF(G108=0,Parametros!$E$8,Parametros!$E$6+Parametros!$E$6*(Parametros!$E$7/G108+I108)/(Parametros!$E$6+Parametros!$E$7/G108+I108)) | K108: 2026-10-09 12:20 | L108: Válido | M108: =IF(L108="Válido","Sim","Não")
A109: 4Bracos_2700_R1110_80W_2026-10-09_12_20.csv | B109: 80W_2700RPM_R1110 | C109: 80 | D109: 2700 | E109: =D109*2/60 | F109: 1110 | G109: 4 | H109: =INDEX(Parametros!$B$2:$B$9,MATCH(G109,Parametros!$A$2:$A$9,0)) | I109: =1/(VALUE(MID(F109,1,1))/Parametros!$E$2+VALUE(MID(F109,2,1))/Parametros!$E$3+VALUE(MID(F109,3,1))/Parametros!$E$4+VALUE(MID(F109,4,1))/Parametros!$E$5) | J109: =IF(G109=0,Parametros!$E$8,Parametros!$E$6+Parametros!$E$6*(Parametros!$E$7/G109+I109)/(Parametros!$E$6+Parametros!$E$7/G109+I109)) | K109: 2026-10-09 12:20 | L109: Válido | M109: =IF(L109="Válido","Sim","Não")
... A129: 0Bracos_3000_R0001_80W_2026-10-09_12_20.csv | B129: 80W_3000RPM_R0001 | C129: 80 | D129: 3000 | E129: =D129*2/60 | F129: 0001 | G129: 0 | H129: =INDEX(Parametros!$B$2:$B$9,MATCH(G129,Parametros!$A$2:$A$9,0)) | I129: =1/(VALUE(MID(F129,1,1))/Parametros!$E$2+VALUE(MID(F129,2,1))/Parametros!$E$3+VALUE(MID(F129,3,1))/Parametros!$E$4+VALUE(MID(F129,4,1))/Parametros!$E$5) | J129: =IF(G129=0,Parametros!$E$8,Parametros!$E$6+Parametros!$E$6*(Parametros!$E$7/G129+I129)/(Parametros!$E$6+Parametros!$E$7/G129+I129)) | K129: 2026-10-09 12:20 | L129: Válido | M129: =IF(L129="Válido","Sim","Não")
...

Sheet Resumo
A1: Ensaios válidos por condição
A3: Potência (W) | B3: 2700 | C3: 3000 | D3: 3500 | E3: Total
A4: 80 | B4: =COUNTIFS(Ensaios!$C$2:$C$1137,$A4,Ensaios!$D$2:$D$1137,B$3,Ensaios!$M$2:$M$1137,"Sim") | C4: =COUNTIFS(Ensaios!$C$2:$C$1137,$A4,Ensaios!$D$2:$D$1137,C$3,Ensaios!$M$2:$M$1137,"Sim") | D4: =COUNTIFS(Ensaios!$C$2:$C$1137,$A4,Ensaios!$D$2:$D$1137,D$3,Ensaios!$M$2:$M$1137,"Sim") | E4: =SUM(B4:D4)
A5: 150 | B5: =COUNTIFS(Ensaios!$C$2:$C$1137,$A5,Ensaios!$D$2:$D$1137,B$3,Ensaios!$M$2:$M$1137,"Sim") | C5: =COUNTIFS(Ensaios!$C$2:$C$1137,$A5,Ensaios!$D$2:$D$1137,C$3,Ensaios!$M$2:$M$1137,"Sim") | D5: =COUNTIFS(Ensaios!$C$2:$C$1137,$A5,Ensaios!$D$2:$D$1137,D$3,Ensaios!$M$2:$M$1137,"Sim") | E5: =SUM(B5:D5)
A6: 210 | B6: =COUNTIFS(Ensaios!$C$2:$C$1137,$A6,Ensaios!$D$2:$D$1137,B$3,Ensaios!$M$2:$M$1137,"Sim") | C6: =COUNTIFS(Ensaios!$C$2:$C$1137,$A6,Ensaios!$D$2:$D$1137,C$3,Ensaios!$M$2:$M$1137,"Sim") | D6: =COUNTIFS(Ensaios!$C$2:$C$1137,$A6,Ensaios!$D$2:$D$1137,D$3,Ensaios!$M$2:$M$1137,"Sim") | E6: =SUM(B6:D6)
A7: Total | B7: =SUM(B4:B6) | C7: =SUM(C4:C6) | D7: =SUM(D4:D6) | E7: =SUM(E4:E6)
A9: Arquivos por status
A10: Válido | B10: =COUNTIF(Ensaios!$L$2:$L$1137,A10)
A11: Substituído (refeito) | B11: =COUNTIF(Ensaios!$L$2:$L$1137,A11)
A12: Falha nos braços de capacitor | B12: =COUNTIF(Ensaios!$L$2:$L$1137,A12)
A13: Motor fora de regime | B13: =COUNTIF(Ensaios!$L$2:$L$1137,A13)
A14: Patamar baixo de ripple (suspeita DAQ) | B14: =COUNTIF(Ensaios!$L$2:$L$1137,A14)
A15: Total de arquivos | B15: =SUM(B10:B14)
A16: Esperado por condição: 15 códigos × 8 braços = 120 ensaios

Sheet Parametros
A1: Braços ativos | B1: Capacitância (µF) | D1: Parâmetro | E1: Valor (Ω) | F1: Descrição
A2: 0 | B2: 324 | D2: R_a1 | E2: 0.11 | F2: Braço de resistor 1 (código 1xxx): só MOSFET
A3: 1 | B3: 490 | D3: R_a2 | E3: 0.58 | F3: Braço 2 (x1xx): MOSFET + resistor 0,47 Ω
A4: 2 | B4: 626 | D4: R_a3 | E4: 0.345 | F4: Braço 3 (xx1x): MOSFET + 2×0,47 Ω em paralelo
A5: 3 | B5: 739 | D5: R_a4 | E5: 0.45 | F5: Braço 4 (xxx1): MOSFET + 2×0,68 Ω em paralelo
A6: 4 | B6: 837 | D6: R_fixo | E6: 0.1 | F6: Resistência série fixa do circuito
A7: 5 | B7: 922 | D7: R_bracos_cap | E7: 0.51 | F7: Resistência equivalente de 1 braço de capacitor (divide pelo nº de braços)
A8: 6 | B8: 994 | D8: R_sem_bracos | E8: 0.2 | F8: Resistência série adotada com 0 braços ativos
A9: 7 | B9: 1056
D10: Fonte: valores de calibração da jiga usados nos scripts MATLAB do repositório (plot_matriz_correlacao_*.m, analisa_psd_bracos.m).
D11: R = R_sem_bracos se 0 braços; senão R = R_fixo + R_fixo·S/(R_fixo + S), com S = R_bracos_cap/n + R_paralelo dos braços de resistor ativos.

Sheet Legenda
A1: Labels de todos os ensaios estruturados da jiga (gerado em 2026-10-09)
A3: Aba Ensaios: uma linha por arquivo CSV em Dados_Ensaios/<Potência>_<Rotação>RPM_R<código>/.
A4: Capacitância e Resistência série são calculadas por fórmula a partir da aba Parametros (valores de calibração em azul); alterar os parâmetros atualiza todas as linhas.
A5: f elétrica = Rotação × 2 pares de polos / 60.
A6: Status (texto em azul, editável pela lista suspensa) foi atribuído pelas checagens automáticas de 2026-10-09:
A7: • Substituído (refeito): existe um arquivo mais novo para a mesma potência, rotação, código e braços.
A8: • Motor fora de regime: fundamental da tensão do motor a mais de 8 Hz de rotação/30 (resolução da FFT = 10 Hz) ou tensão do motor < 100 V.
A9: • Falha nos braços de capacitor: ripple de 120 Hz com 7 braços / com 0 braços > 0,55 na configuração (esperado ~0,35).
A10: • Patamar baixo de ripple (suspeita DAQ): só 80W; ripple×C mediano da configuração < 620 (patamar normal ~730). Associado aos reinícios da placa de aquisição.
A11: • Válido: passou em todas as checagens.
A12: 'Usar na análise' = Sim apenas para status Válido (fórmula).
A13: Aba Resumo: contagem de ensaios válidos por condição e de arquivos por status (fórmulas).
